Workbook

Sheet README
B2: PRIVATE CREDIT - AI CONCENTRATION FORWARD MODEL
B3: Live model behind section 3 of private_credit_consolidated_final_section.md
B6: COLOUR KEY
B7: GREEN | C7: You update these.
B8: BLUE | C8: Sourced and locked. Changing one breaks a citation.
B9: YELLOW | C9: Judgement. Change only with a stated reason.
B10: PINK | C10: Required and currently missing. Blocking.
B11: GREY | C11: Calculated. Do not type over.
B13: THE THREE COHORTS
B14: Narrow | C14: AI-native borrowers, direct loans. ~8% today -> ~10% by 2030 (range 5-13%). The only sleeve with a matched numerator and denominator.
B15: Broad | C15: AI infrastructure via ABF / private IG / project finance. $0.8-1.4tn of forecast financing and NO published denominator. Report in dollars.
B16: Disruption | C16: Software / technology, 19-26%. OPPOSITE SIGN. Never add to the other two.
B18: THE KEY RESULT
B19: Convergence | C19: The 2030 weight converges to the AI share of NEW ORIGINATIONS, not to any capex forecast. With a 4.7yr loan life on a book growing 11.2%, five years covers 82% of that convergence. BIS's own $300-600bn implies a 7-15% origination share, against an OECD/FSB 2025 deal share of 34%. See the Origination_Convergence tab.
B20: Run-rate | C20: $200bn stock / 4.7yr life = $42.6bn/yr just to stand still, against >$40bn observed in 2025. The 2025 pace IS the replacement rate. BIS's own $300-600bn projection therefore requires originations to rise 1.6x to 3.2x - a requirement no source states.
B22: SENSITIVITIES
B23: g 11.2% -> 14.0% | C23: moves the narrow 2030 result about 1.1pp lower at the base case.
B24: D0 +/- $250bn | C24: moves the narrow result about 1.0pp inversely.
B25: sigma +5pp | C25: moves the convergence result about 4.7pp - by far the largest single lever.
B27: WHAT NOT TO DO
B28: Do not | C28: divide $800bn by Preqin's $4.5tn. That gives ~18% and is wrong: Preqin explicitly excludes ABF, private IG and insurance SMAs, which is exactly where the $800bn goes.
B29: Do not | C29: add the narrow 8% and the disruption 19-26% to report '27-34%'. Different universes, different taxonomies, opposite signs, unmeasured overlap.
B30: Do not | C30: add cumulative gross financing to today's stock. See Broad_Sleeve for the conversion.
B32: VERIFICATION | C32: Every percentage published in the markdown reconciles to this workbook. Rebuild with .codex_work/build_pc_xlsx.py; check with .codex_work/verify_pc_xlsx.py.

Sheet Inputs
B2: INPUTS - PRIVATE CREDIT AI CONCENTRATION
B3: Edit GREEN only. Yellow = judgement. Pink = required and currently missing.
B4: Input | C4: Value | D4: Unit | E4: Status | F4: Source / note
B5: NARROW COHORT - AI-native borrowers, direct loans
B6: S0 AI-related direct loans outstanding | C6: 200 | D6: $bn | E6: SOURCED | F6: BIS Bulletin 120 (Jan-2026): 'more than $200bn'. NOT locally held - external link only.
B7: W0 share of outstanding direct loans | C7: 0.08 | D7: % | E7: SOURCED | F7: BIS Bulletin 120: 'almost 8%'. Numerator and denominator are matched in the same PitchBook sample.
B8: D0 matched direct-loan universe = S0 / W0 | C8: =C6/C7 | D8: $bn | E8: CALC | F8: Reconciled bottom-up below. This is a GROSS outstanding loan basis, not AUM.
B9: h horizon | C9: 5 | D9: yrs | E9: SOURCED | F9: End-2025 to end-2030.
B10: M average AI loan maturity | C10: 4.7 | D10: yrs | E10: SOURCED | F10: BIS Bulletin 120: 4.7yr AI vs 4.8yr other. Implies 1/M = 21.3% of stock rolls off each year.
B11: 2025 AI originations | C11: 40 | D11: $bn | E11: SOURCED | F11: BIS Bulletin 120: 'more than $40bn' in 2025, from ~$3bn in 2010.
B12: g non-AI growth - low | C12: 0.112 | D12: % | E12: SOURCED | F12: Preqin Private Markets in 2030 p.19: direct lending AUM CAGR 2024-2030F, 'approaching $1.7tn by 2030F'.
B13: Preqin total private credit AUM 2024 | C13: 2100 | D13: $bn | E13: SOURCED | F13: Preqin Private Markets in 2030 p.17.
B14: Preqin total private credit AUM 2030F | C14: 4500 | D14: $bn | E14: SOURCED | F14: Same. 'more than double the 2024 figure'.
B15: g non-AI growth - base | C15: =(C14/C13)^(1/6)-1 | D15: % | E15: CALC | F15: Derived, not typed, so it matches the section exactly: 6-year CAGR from the two Preqin points.
B16: g non-AI growth - high | C16: 0.14 | D16: % | E16: SOURCED | F16: JPM AI Capex 2.0 p.41: private credit universe CAGR since 2020. NOTE all three are TOTAL rates incl. AI, so using them as the non-AI rate biases results DOWN.
B17: BIS 2030 projection - low | C17: 300 | D17: $bn | E17: SOURCED | F17: BIS Bulletin 120: $300-600bn outstanding by 2030.
B18: BIS 2030 projection - midpoint | C18: 450 | D18: $bn | E18: JUDGEMENT | F18: Midpoint of the BIS range. Not itself published.
B19: BIS 2030 projection - high | C19: 600 | D19: $bn | E19: SOURCED | F19: BIS Bulletin 120.
B20: DENOMINATOR RECONCILIATION - bottom-up rebuild of D0
B21: Drawdown fund AUM (global) | C21: 1810 | D21: $bn | E21: SOURCED | F21: JPM AI Capex 2.0 p.41, citing Preqin at 30-Sep. Excludes BDCs and semi-liquid vehicles.
B22: of which dry powder | C22: 543 | D22: $bn | E22: SOURCED | F22: JPM p.41 / Preqin. Record high.
B23: of which invested | C23: =C21-C22 | D23: $bn | E23: CALC | F23: JPM states $1.27tn. This is deployed fund capital, before fund-level leverage.
B24: BDC gross asset value | C24: 500 | D24: $bn | E24: SOURCED | F24: Preqin, Private Markets Unpacked: BDCs Examined p.2, YE2025. 188 vehicles.
B25: BDC net asset value | C25: 250 | D25: $bn | E25: SOURCED | F25: Same. Gross/net = 2.0x, i.e. 1.0x debt-to-equity.
B26: BDC gross-to-net | C26: =C24/C25 | D26: x | E26: CALC
B27: Subtotal before drawdown-fund leverage | C27: =C23+C24 | D27: $bn | E27: CALC
B28: Residual vs BIS-implied D0 | C28: =C8-C27 | D28: $bn | E28: CALC | F28: INFERENCE, not a published figure. The one soft joint in the denominator.
B29: implied leverage on invested capital | C29: =C28/C23 | D29: x | E29: CALC | F29: 0.5-1.0x is the typical direct-lending fund range, and BDCs run 1.0x. Reconciles without strain.
B30: BROAD SLEEVE - AI infrastructure private capital
B31: Morgan Stanley - private credit for data centres | C31: 800 | D31: $bn | E31: SOURCED | F31: MS Bridging a $1.5tn Data Center Financing Gap pp.6-9,34. Cumulative GROSS 2025-28, led by ABF.
B32: spread over | C32: 4 | D32: yrs | E32: SOURCED | F32: 2025-2028 inclusive.
B33: Apollo - private IG financing of AI ecosystem | C33: 1000 | D33: $bn | E33: SOURCED | F33: Apollo 2026 Midyear Credit Outlook p.16: 'private IG will likely provide more than $1 trillion of financing'.
B34: J.P. Morgan - call on private credit/alt capital | C34: 1400 | D34: $bn | E34: SOURCED | F34: JPM AI Capex 2.0 p.47. NOT a credit numerator - explicitly includes infrastructure EQUITY (e.g. Blue Owl's ~$7bn equity in the ~$27bn Hyperion project).
B35: Broad-cohort 2030 denominator | D35: $bn | E35: MISSING | F35: BLANK AND BLOCKING. No source publishes it. Preqin's $4.5tn EXPLICITLY excludes ABF, private IG and insurance SMAs (Private Markets in 2030 p.17) - the exact three channels this sleeve uses. Do not substitute $4.5tn.
B36: MORGAN STANLEY $800bn DECOMPOSITION - reproducibility check
B37: Total data-centre spend 2025-28 | C37: 2900 | D37: $bn | E37: SOURCED | F37: MS, as printed.
B38: less hyperscaler cash flow | C38: 1400 | D38: $bn | E38: SOURCED | F38: MS, as printed.
B39: less corporate debt | C39: 200 | D39: $bn | E39: SOURCED | F39: MS, as printed.
B40: less securitized debt | C40: 150 | D40: $bn | E40: SOURCED | F40: MS, as printed.
B41: x debt share of residual gap | C41: 0.7 | D41: % | E41: SOURCED | F41: MS 70/30 debt/other split, supported by 70-80% data-centre LTV, Abilene >60% construction-loan funding, Stargate 10-20% equity.
...

Sheet Narrow_Scenario
B2: NARROW COHORT - END-2030 WEIGHT
B3: W = (S0 + N) / ((D0 - S0)(1+g)^h + S0 + N). N enters numerator AND denominator.
B5: Route | C5: N ($bn) | D5: g = low | E5: g = base | F5: g = high | G5: Note
B6: B - Flat originations (FLOOR) | C6: =0 | D6: =(Inputs!C6+$C6)/((Inputs!C8-Inputs!C6)*(1+Inputs!C12)^Inputs!C9+Inputs!C6+$C6) | E6: =(Inputs!C6+$C6)/((Inputs!C8-Inputs!C6)*(1+Inputs!C15)^Inputs!C9+Inputs!C6+$C6) | F6: =(Inputs!C6+$C6)/((Inputs!C8-Inputs!C6)*(1+Inputs!C16)^Inputs!C9+Inputs!C6+$C6) | G6: 2025 pace persists. $200bn/4.7yr = $42.6bn/yr replacement need vs >$40bn observed.
B7: C - Parity growth | C7: derived (varies with g) | D7: =(Inputs!C6+(Inputs!C6*((1+Inputs!C12)^Inputs!C9-1)))/((Inputs!C8-Inputs!C6)*(1+Inputs!C12)^Inputs!C9+Inputs!C6+(Inputs!C6*((1+Inputs!C12)^Inputs!C9-1))) | E7: =(Inputs!C6+(Inputs!C6*((1+Inputs!C15)^Inputs!C9-1)))/((Inputs!C8-Inputs!C6)*(1+Inputs!C15)^Inputs!C9+Inputs!C6+(Inputs!C6*((1+Inputs!C15)^Inputs!C9-1))) | F7: =(Inputs!C6+(Inputs!C6*((1+Inputs!C16)^Inputs!C9-1)))/((Inputs!C8-Inputs!C6)*(1+Inputs!C16)^Inputs!C9+Inputs!C6+(Inputs!C6*((1+Inputs!C16)^Inputs!C9-1))) | G7: AI grows exactly with the asset class. Algebraically collapses to S0/D0 = W0 at every g - a behaviour check on the identity.
B8: A-low - BIS $300bn stock | C8: =Inputs!C17-Inputs!C6 | D8: =(Inputs!C6+$C8)/((Inputs!C8-Inputs!C6)*(1+Inputs!C12)^Inputs!C9+Inputs!C6+$C8) | E8: =(Inputs!C6+$C8)/((Inputs!C8-Inputs!C6)*(1+Inputs!C15)^Inputs!C9+Inputs!C6+$C8) | F8: =(Inputs!C6+$C8)/((Inputs!C8-Inputs!C6)*(1+Inputs!C16)^Inputs!C9+Inputs!C6+$C8) | G8: BIS Bulletin 120 low end.
B9: A-mid - BIS $450bn stock (BASE) | C9: =Inputs!C18-Inputs!C6 | D9: =(Inputs!C6+$C9)/((Inputs!C8-Inputs!C6)*(1+Inputs!C12)^Inputs!C9+Inputs!C6+$C9) | E9: =(Inputs!C6+$C9)/((Inputs!C8-Inputs!C6)*(1+Inputs!C15)^Inputs!C9+Inputs!C6+$C9) | F9: =(Inputs!C6+$C9)/((Inputs!C8-Inputs!C6)*(1+Inputs!C16)^Inputs!C9+Inputs!C6+$C9) | G9: Midpoint of the BIS range.
B10: A-high - BIS $600bn stock | C10: =Inputs!C19-Inputs!C6 | D10: =(Inputs!C6+$C10)/((Inputs!C8-Inputs!C6)*(1+Inputs!C12)^Inputs!C9+Inputs!C6+$C10) | E10: =(Inputs!C6+$C10)/((Inputs!C8-Inputs!C6)*(1+Inputs!C15)^Inputs!C9+Inputs!C6+$C10) | F10: =(Inputs!C6+$C10)/((Inputs!C8-Inputs!C6)*(1+Inputs!C16)^Inputs!C9+Inputs!C6+$C10) | G10: BIS Bulletin 120 high end.
B12: PREFERRED VIEW: ~10% by end-2030, range 5-14%
B13: Base = Route A-mid across the g band (9.4-10.3%), independently corroborated by the Route D recursion at the origination share BIS implies (10.6%). Floor is Route B - a FALLING weight, which the prior version of this section had no case for.

Sheet Origination_Convergence
B2: ROUTE D - THE WEIGHT CONVERGES TO THE ORIGINATION SHARE
B3: S(t+1) = S(t)(1 - 1/M) + sigma x D(t) x (g + 1/M). Steady state: S/D -> sigma exactly.
B4: Gross originations must be D(g + 1/M), not D/M: a book growing at g needs new lending to cover run-off AND growth. Error decays by (1-1/M)/(1+g) a year, so five years covers 82% of the gap.
B6: Series | C6: 2025 | D6: 2026 | E6: 2027 | F6: 2028 | G6: 2029 | H6: 2030 | I6: Note
B7: D(t) total direct loans | C7: =Inputs!C8 | D7: =C7*(1+Inputs!C12) | E7: =D7*(1+Inputs!C12) | F7: =E7*(1+Inputs!C12) | G7: =F7*(1+Inputs!C12) | H7: =G7*(1+Inputs!C12) | I7: Grown at g-low (Preqin direct lending 11.2%).
B8: AI STOCK S(t) BY ORIGINATION SHARE
B9: 0.049 | C9: =Inputs!C6 | D9: =C9*(1-1/Inputs!C10)+$B9*C7*(Inputs!C12+1/Inputs!C10) | E9: =D9*(1-1/Inputs!C10)+$B9*D7*(Inputs!C12+1/Inputs!C10) | F9: =E9*(1-1/Inputs!C10)+$B9*E7*(Inputs!C12+1/Inputs!C10) | G9: =F9*(1-1/Inputs!C10)+$B9*F7*(Inputs!C12+1/Inputs!C10) | H9: =G9*(1-1/Inputs!C10)+$B9*G7*(Inputs!C12+1/Inputs!C10) | I9: Flat originations at the 2025 pace (>$40bn). Corroborates the prior draft's ~4%.
B10: 0.069 | C10: =Inputs!C6 | D10: =C10*(1-1/Inputs!C10)+$B10*C7*(Inputs!C12+1/Inputs!C10) | E10: =D10*(1-1/Inputs!C10)+$B10*D7*(Inputs!C12+1/Inputs!C10) | F10: =E10*(1-1/Inputs!C10)+$B10*E7*(Inputs!C12+1/Inputs!C10) | G10: =F10*(1-1/Inputs!C10)+$B10*F7*(Inputs!C12+1/Inputs!C10) | H10: =G10*(1-1/Inputs!C10)+$B10*G7*(Inputs!C12+1/Inputs!C10) | I10: Implied by BIS's own $300bn low case
B11: 0.09 | C11: =Inputs!C6 | D11: =C11*(1-1/Inputs!C10)+$B11*C7*(Inputs!C12+1/Inputs!C10) | E11: =D11*(1-1/Inputs!C10)+$B11*D7*(Inputs!C12+1/Inputs!C10) | F11: =E11*(1-1/Inputs!C10)+$B11*E7*(Inputs!C12+1/Inputs!C10) | G11: =F11*(1-1/Inputs!C10)+$B11*F7*(Inputs!C12+1/Inputs!C10) | H11: =G11*(1-1/Inputs!C10)+$B11*G7*(Inputs!C12+1/Inputs!C10) | I11: OECD 2024 deal share
B12: 0.111 | C12: =Inputs!C6 | D12: =C12*(1-1/Inputs!C10)+$B12*C7*(Inputs!C12+1/Inputs!C10) | E12: =D12*(1-1/Inputs!C10)+$B12*D7*(Inputs!C12+1/Inputs!C10) | F12: =E12*(1-1/Inputs!C10)+$B12*E7*(Inputs!C12+1/Inputs!C10) | G12: =F12*(1-1/Inputs!C10)+$B12*F7*(Inputs!C12+1/Inputs!C10) | H12: =G12*(1-1/Inputs!C10)+$B12*G7*(Inputs!C12+1/Inputs!C10) | I12: Implied by the BIS $450bn midpoint
B13: 0.154 | C13: =Inputs!C6 | D13: =C13*(1-1/Inputs!C10)+$B13*C7*(Inputs!C12+1/Inputs!C10) | E13: =D13*(1-1/Inputs!C10)+$B13*D7*(Inputs!C12+1/Inputs!C10) | F13: =E13*(1-1/Inputs!C10)+$B13*E7*(Inputs!C12+1/Inputs!C10) | G13: =F13*(1-1/Inputs!C10)+$B13*F7*(Inputs!C12+1/Inputs!C10) | H13: =G13*(1-1/Inputs!C10)+$B13*G7*(Inputs!C12+1/Inputs!C10) | I13: Implied by BIS's own $600bn high case
B14: 0.17 | C14: =Inputs!C6 | D14: =C14*(1-1/Inputs!C10)+$B14*C7*(Inputs!C12+1/Inputs!C10) | E14: =D14*(1-1/Inputs!C10)+$B14*D7*(Inputs!C12+1/Inputs!C10) | F14: =E14*(1-1/Inputs!C10)+$B14*E7*(Inputs!C12+1/Inputs!C10) | G14: =F14*(1-1/Inputs!C10)+$B14*F7*(Inputs!C12+1/Inputs!C10) | H14: =G14*(1-1/Inputs!C10)+$B14*G7*(Inputs!C12+1/Inputs!C10) | I14: FSB five-year average deal share
B15: 0.34 | C15: =Inputs!C6 | D15: =C15*(1-1/Inputs!C10)+$B15*C7*(Inputs!C12+1/Inputs!C10) | E15: =D15*(1-1/Inputs!C10)+$B15*D7*(Inputs!C12+1/Inputs!C10) | F15: =E15*(1-1/Inputs!C10)+$B15*E7*(Inputs!C12+1/Inputs!C10) | G15: =F15*(1-1/Inputs!C10)+$B15*F7*(Inputs!C12+1/Inputs!C10) | H15: =G15*(1-1/Inputs!C10)+$B15*G7*(Inputs!C12+1/Inputs!C10) | I15: OECD and FSB 2025 deal share - they agree
B17: IMPLIED WEIGHT W(t) = S(t) / D(t)
B18: =$B$9 | C18: =C9/C7 | D18: =D9/D7 | E18: =E9/E7 | F18: =F9/F7 | G18: =G9/G7 | H18: =H9/H7 | I18: 2030 column is the published figure.
B19: =$B$10 | C19: =C10/C7 | D19: =D10/D7 | E19: =E10/E7 | F19: =F10/F7 | G19: =G10/G7 | H19: =H10/H7 | I19: 2030 column is the published figure.
B20: =$B$11 | C20: =C11/C7 | D20: =D11/D7 | E20: =E11/E7 | F20: =F11/F7 | G20: =G11/G7 | H20: =H11/H7 | I20: 2030 column is the published figure.
B21: =$B$12 | C21: =C12/C7 | D21: =D12/D7 | E21: =E12/E7 | F21: =F12/F7 | G21: =G12/G7 | H21: =H12/H7 | I21: 2030 column is the published figure.
B22: =$B$13 | C22: =C13/C7 | D22: =D13/D7 | E22: =E13/E7 | F22: =F13/F7 | G22: =G13/G7 | H22: =H13/H7 | I22: 2030 column is the published figure.
B23: =$B$14 | C23: =C14/C7 | D23: =D14/D7 | E23: =E14/E7 | F23: =F14/F7 | G23: =G14/G7 | H23: =H14/H7 | I23: 2030 column is the published figure.
B24: =$B$15 | C24: =C15/C7 | D24: =D15/D7 | E24: =E15/E7 | F24: =F15/F7 | G24: =G15/G7 | H24: =H15/H7 | I24: 2030 column is the published figure.
B26: MONITORING: this is the highest-value indicator on the dashboard. | C26: =Inputs!C7 | D26: sigma = W0 = 8% must hold the weight flat at 8.00% in every year. Set any sigma cell above to 8% to confirm.
B27: The 2030 weight converges to the AI share of NEW ORIGINATIONS and to nothing else. It discriminates between a 4% and a 13% outcome, and it is observable from deal tapes and BDC filings long before it appears in stock.

Sheet Broad_Sleeve
B2: BROAD SLEEVE - AI INFRASTRUCTURE PRIVATE CREDIT
B3: Numerators are CUMULATIVE GROSS financing. There is no published denominator.
B5: Source | C5: $bn | D5: Window | E5: Basis | F5: Note
B6: Morgan Stanley | C6: =Inputs!C31 | D6: 2025-28 | E6: cumulative gross, led by ABF | F6: Fully reproducible from its own components - see the Inputs decomposition block.
B7: Apollo | C7: =Inputs!C33 | D7: to 2030 | E7: cumulative gross, private IG | F7: 'private IG will likely provide more than $1 trillion of financing'.
B8: J.P. Morgan | C8: =Inputs!C34 | D8: to 2030 | E8: private credit / ALTERNATIVE capital | F8: Includes infrastructure EQUITY. Not a credit numerator.
B10: GROSS FLOW -> STANDING STOCK (the conversion that 'add $800bn to $200bn' gets wrong)
B11: MS annual pace = $800bn / 4yr | C11: =Inputs!C31/Inputs!C32
B12: Peak standing stock, end-2028 | C12: =$C$11*(1+(1-1/Inputs!C10)+(1-1/Inputs!C10)^2+(1-1/Inputs!C10)^3) | F12: Four vintages 2025-28, each running off at 1/M per year.
B13: End-2030 if originations stop after 2028 | C13: =$C$11*((1-1/Inputs!C10)^2+(1-1/Inputs!C10)^3+(1-1/Inputs!C10)^4+(1-1/Inputs!C10)^5) | F13: The MS window read literally.
B14: End-2030 if the pace continues to 2030 | C14: =$C$11*(1+(1-1/Inputs!C10)+(1-1/Inputs!C10)^2+(1-1/Inputs!C10)^3+(1-1/Inputs!C10)^4+(1-1/Inputs!C10)^5) | F14: Six vintages 2025-30.
B16: IF A DENOMINATOR IS SUPPLIED (illustration of an identity, NOT an estimate)
B17: Broad 2030 denominator ($bn) | C17: $800bn implies | D17: $1,000bn implies
B18: 4500 | C18: =800/$B18 | D18: =1000/$B18 | F18: <-- Preqin's $4.5tn. Shown ONLY to demonstrate the error: it EXCLUDES ABF, private IG and insurance SMAs by Preqin's own statement. Do not use.
B19: 6000 | C19: =800/$B19 | D19: =1000/$B19
B20: 8000 | C20: =800/$B20 | D20: =1000/$B20
B21: 10000 | C21: =800/$B21 | D21: =1000/$B21

Sheet Sources
B2: SOURCES AND VERIFICATION STATUS
B4: Source | C4: What it supplies | D4: Status | E4: Note
B5: J.P. Morgan, AI Capex 2.0 (Jun-26) | C5: Drawdown AUM $1.81tn; Tech 22%; KBRA software 21%; $1.4tn call | D5: VERIFIED | E5: PDF held in research/. Page refs in the section.
B6: Morgan Stanley, $1.5tn Financing Gap (Jul-25) | C6: $800bn private credit; $2.9tn spend; 70/30 split | D6: VERIFIED | E6: Decomposition reproduces to 0.6%.
B7: Morgan Stanley, Mapping Software Exposure (Feb-26) | C7: 26% software+IT services across 42 public BDCs | D7: VERIFIED | E7: PDF held in research/.
B8: Morgan Stanley, Investor Feedback (Jul-26) | C8: $217/$336/$580bn AI issuance; ABS/CMBS shares | D8: VERIFIED | E8: NOTE: this tracker has NO private-credit column.
B9: Apollo, 2026 Midyear Credit Outlook (Aug-26) | C9: Private IG >$1tn; $90bn IG backstops | D9: VERIFIED | E9: PDF held in research/.
B10: Preqin, Private Markets in 2030 (Oct-25) | C10: $2.1tn->$4.5tn AUM; DL 11.2% CAGR; exclusions | D10: VERIFIED | E10: The stated exclusion of ABF/private IG/insurance SMA is the key finding.
B11: Preqin, BDCs Examined (Jul-26) | C11: $500bn GAV / $250bn NAV; 188 vehicles | D11: VERIFIED | E11: PDF held in research/.
B12: Preqin, Private Credit Q2 2026 (Jul-26) | C12: $99bn Q2 fundraising; BDC gates; AI-software concern | D12: VERIFIED | E12: PDF held in research/.
B13: BIS Bulletin 120 (Jan-26) | C13: $200bn / 8%; >$40bn originations; 4.7yr maturity; $300-600bn 2030 | D13: NOT VERIFIED | E13: External link only. THE ENTIRE NARROW MEASUREMENT DEPENDS ON THIS. Obtain before IC.
B14: BIS Quarterly Review (Mar-26) | C14: SaaS 19% of direct loans; software selloff evidence | D14: NOT VERIFIED | E14: External link only.
B15: BIS Bulletin 128 (Jul-26) | C15: BDC software ~$115bn / ~20%; top-5 37%; 7+ BDC overlap | D15: NOT VERIFIED | E15: External link only.
... B20: PRIOR DRAFT | C20: 'AI originations were ~4% of total direct-loan originations' | D20: UNCORROBORATED | E20: Appears nowhere in this workspace's independent evidence notes. No conclusion depends on it.

Sheet Data_Needed
B2: DATA STILL REQUIRED
B3: Ordered by effect on the published answer.
B5: Input | C5: Cell | D5: Effect on the answer | E5: Where to get it
B6: Broad-cohort 2030 denominator | C6: Inputs!C35 | D6: BLOCKING - the broad sleeve has no percentage without it | E6: Not published. Build from ABF + private IG + insurance SMA + direct lending, or obtain MS Exhibit 11 ABF TAM.
B7: AI share of originations, quarterly | C7: Origination_Convergence row inputs | D7: Drives the entire 4-20% span | E7: Deal tapes; BDC 10-Q loan schedules. The single highest-value series.
B8: House loan-level b and d scores | C8: n/a - replaces the model | D8: Replaces every market proxy with the actual book | E8: Internal. Highest value of any input here.
B9: Preqin Fig 4.1 sub-strategy data pack | C9: Inputs!C12, C8 | D9: Splits BDC from closed-end DL; confirms GAV vs NAV basis | E9: Preqin Pro subscription.
B10: Drawdown-fund leverage, actual | C10: Inputs!C29 | D10: Currently a 0.57x INFERENCE - the soft joint in D0 | E10: Not published. Fund financial statements or manager disclosure.
B11: Morgan Stanley ABF TAM (Exhibit 11) | C11: Inputs!C35 | D11: Would supply the broad denominator directly | E11: Chart is not machine-readable in the local PDF. Request the data pack.
B12: 2026 actual private credit AUM | C12: Inputs!C15 | D12: Preqin's Q2-26 chart is dated Jul-2026 but prints no value | E12: Preqin Pro.
B13: ABS/CMBS take-out rate from private credit | C13: n/a - section 3.6 | D13: Determines whether a FALLING weight is good or bad news | E13: Not quantified by any source. Track named construction loans to securitisation.
B14: The three BIS publications | C14: Inputs!C6, C7, C10, C11, C17-C19 | D14: The entire narrow measurement rests on them | E14: bis.org - free. Verify line-by-line before the paper circulates.
