Workbook

Sheet Final Output
A1: AMD Revenue Model - Scenario Summary
A2: One live effective case plus manually refreshed Bear / Base / Bull snapshots. USD millions.
A4: EFFECTIVE CASE (LIVE)
A5: Segment ($M) | B5: =Assumptions!B$8 -> Q4'25A | C5: =Assumptions!C$8 -> Q1'26A | D5: =Assumptions!D$8 -> Q2'26A | E5: =Assumptions!E$8 -> Q3'26E | F5: =Assumptions!F$8 -> Q4'26E | G5: =Assumptions!G$8 -> FY26E | H5: =Assumptions!H$8 -> Q1'27E | I5: =Assumptions!I$8 -> Q2'27E | ... R5: =Assumptions!R$8 -> NTM E
A6: Data Center | B6: ='Revenue Build'!B8 -> 5380 | C6: ='Revenue Build'!C8 -> 5775 | D6: ='Revenue Build'!D8 -> 6718 | E6: ='Revenue Build'!E8 | F6: ='Revenue Build'!F8 | G6: ='Revenue Build'!G8 | H6: ='Revenue Build'!H8 | I6: ='Revenue Build'!I8 | ... R6: ='Revenue Build'!R8
A7: Client | B7: ='Revenue Build'!B9 -> 0 | C7: ='Revenue Build'!C9 -> 0 | D7: ='Revenue Build'!D9 -> 0 | E7: ='Revenue Build'!E9 -> 0 | F7: ='Revenue Build'!F9 -> 0 | G7: ='Revenue Build'!G9 | H7: ='Revenue Build'!H9 -> 0 | I7: ='Revenue Build'!I9 -> 0 | ... R7: ='Revenue Build'!R9
A8: Gaming | B8: ='Revenue Build'!B10 -> 0 | C8: ='Revenue Build'!C10 -> 0 | D8: ='Revenue Build'!D10 -> 0 | E8: ='Revenue Build'!E10 -> 0 | F8: ='Revenue Build'!F10 -> 0 | G8: ='Revenue Build'!G10 | H8: ='Revenue Build'!H10 -> 0 | I8: ='Revenue Build'!I10 -> 0 | ... R8: ='Revenue Build'!R10
A9: Embedded | B9: ='Revenue Build'!B11 -> 0 | C9: ='Revenue Build'!C11 -> 0 | D9: ='Revenue Build'!D11 -> 0 | E9: ='Revenue Build'!E11 -> 0 | F9: ='Revenue Build'!F11 -> 0 | G9: ='Revenue Build'!G11 | H9: ='Revenue Build'!H11 -> 0 | I9: ='Revenue Build'!I11 -> 0 | ... R9: ='Revenue Build'!R11
A10: Total AMD | B10: =IF(COUNT(B6:B9)=0,"",SUM(B6:B9)) -> 5380 | C10: =IF(COUNT(C6:C9)=0,"",SUM(C6:C9)) -> 5775 | D10: =IF(COUNT(D6:D9)=0,"",SUM(D6:D9)) -> 6718 | E10: =IF(COUNT(E6:E9)=0,"",SUM(E6:E9)) -> 0 | F10: =IF(COUNT(F6:F9)=0,"",SUM(F6:F9)) -> 0 | G10: =IF(COUNT(G6:G9)=0,"",SUM(G6:G9)) | H10: =IF(COUNT(H6:H9)=0,"",SUM(H6:H9)) -> 0 | I10: =IF(COUNT(I6:I9)=0,"",SUM(I6:I9)) -> 0 | ... R10: =IF(COUNT(R6:R9)=0,"",SUM(R6:R9))
A13: BEAR CASE - MANUAL SNAPSHOT (paste values)
A14: Segment ($M) | B14: =Assumptions!B$8 -> Q4'25A | C14: =Assumptions!C$8 -> Q1'26A | D14: =Assumptions!D$8 -> Q2'26A | E14: =Assumptions!E$8 -> Q3'26E | F14: =Assumptions!F$8 -> Q4'26E | G14: =Assumptions!G$8 -> FY26E | H14: =Assumptions!H$8 -> Q1'27E | I14: =Assumptions!I$8 -> Q2'27E | ... R14: =Assumptions!R$8 -> NTM E
A15: Data Center
A16: Client
A17: Gaming
A18: Embedded
A19: Total AMD | B19: =IF(COUNT(B15:B18)=0,"",SUM(B15:B18)) | C19: =IF(COUNT(C15:C18)=0,"",SUM(C15:C18)) | D19: =IF(COUNT(D15:D18)=0,"",SUM(D15:D18)) | E19: =IF(COUNT(E15:E18)=0,"",SUM(E15:E18)) | F19: =IF(COUNT(F15:F18)=0,"",SUM(F15:F18)) | G19: =IF(COUNT(G15:G18)=0,"",SUM(G15:G18)) | H19: =IF(COUNT(H15:H18)=0,"",SUM(H15:H18)) | I19: =IF(COUNT(I15:I18)=0,"",SUM(I15:I18)) | ... R19: =IF(COUNT(R15:R18)=0,"",SUM(R15:R18))
A22: BASE CASE - MANUAL SNAPSHOT (paste values)
A23: Segment ($M) | B23: =Assumptions!B$8 -> Q4'25A | C23: =Assumptions!C$8 -> Q1'26A | D23: =Assumptions!D$8 -> Q2'26A | E23: =Assumptions!E$8 -> Q3'26E | F23: =Assumptions!F$8 -> Q4'26E | G23: =Assumptions!G$8 -> FY26E | H23: =Assumptions!H$8 -> Q1'27E | I23: =Assumptions!I$8 -> Q2'27E | ... R23: =Assumptions!R$8 -> NTM E
A24: Data Center
A25: Client
A26: Gaming
A27: Embedded
A28: Total AMD | B28: =IF(COUNT(B24:B27)=0,"",SUM(B24:B27)) | C28: =IF(COUNT(C24:C27)=0,"",SUM(C24:C27)) | D28: =IF(COUNT(D24:D27)=0,"",SUM(D24:D27)) | E28: =IF(COUNT(E24:E27)=0,"",SUM(E24:E27)) | F28: =IF(COUNT(F24:F27)=0,"",SUM(F24:F27)) | G28: =IF(COUNT(G24:G27)=0,"",SUM(G24:G27)) | H28: =IF(COUNT(H24:H27)=0,"",SUM(H24:H27)) | I28: =IF(COUNT(I24:I27)=0,"",SUM(I24:I27)) | ... R28: =IF(COUNT(R24:R27)=0,"",SUM(R24:R27))
A31: BULL CASE - MANUAL SNAPSHOT (paste values)
A32: Segment ($M) | B32: =Assumptions!B$8 -> Q4'25A | C32: =Assumptions!C$8 -> Q1'26A | D32: =Assumptions!D$8 -> Q2'26A | E32: =Assumptions!E$8 -> Q3'26E | F32: =Assumptions!F$8 -> Q4'26E | G32: =Assumptions!G$8 -> FY26E | H32: =Assumptions!H$8 -> Q1'27E | I32: =Assumptions!I$8 -> Q2'27E | ... R32: =Assumptions!R$8 -> NTM E
A33: Data Center
A34: Client
A35: Gaming
A36: Embedded
A37: Total AMD | B37: =IF(COUNT(B33:B36)=0,"",SUM(B33:B36)) | C37: =IF(COUNT(C33:C36)=0,"",SUM(C33:C36)) | D37: =IF(COUNT(D33:D36)=0,"",SUM(D33:D36)) | E37: =IF(COUNT(E33:E36)=0,"",SUM(E33:E36)) | F37: =IF(COUNT(F33:F36)=0,"",SUM(F33:F36)) | G37: =IF(COUNT(G33:G36)=0,"",SUM(G33:G36)) | H37: =IF(COUNT(H33:H36)=0,"",SUM(H33:H36)) | I37: =IF(COUNT(I33:I36)=0,"",SUM(I33:I36)) | ... R37: =IF(COUNT(R33:R36)=0,"",SUM(R33:R36))
A41: MODEL STATUS AND WORKFLOW
A42: Stage | B42: Data Center live (Server + AI). Client / Gaming / Embedded pending.
A43: Period axis | B43: 13 quarters (Q4'25A - Q4'28E), 3 fiscal years, NTM. 3 actual quarters this cycle.
A44: Data Center split | B44: Server + AI only. MI450 sits inside AI.
A45: Drivers | B45: Six scenario anchors on Assumptions. Every quarter in between is interpolated, not typed.
A46: Blocking input | B46: AI current and long-term growth anchors, Bear / Base / Bull - Assumptions rows 35-36.
A47: Data Center check | B47: ='Data Center'!B42 -> OK
A48: Workflow | B48: Pick the scenario on Assumptions!B5, recalculate, then copy B6:R9 above and paste-special VALUES into the matching snapshot block.
A50: Blue on yellow = input | D50: Black = formula / actual | G50: Green = link to another sheet | J50: Red = external reference

Sheet Revenue Build
A1: AMD Revenue Build - Staging Layer
A2: One live scenario. Data Center is built bottom-up on its own sheet; Client, Gaming and Embedded are blank inputs until their driver builds are added.
A4: Active scenario | B4: =Assumptions!$B$5 -> Base
A6: EFFECTIVE CASE BUILD - 13 quarters, 3 fiscal years, NTM
A7: Segment ($M) | B7: =Assumptions!B$8 -> Q4'25A | C7: =Assumptions!C$8 -> Q1'26A | D7: =Assumptions!D$8 -> Q2'26A | E7: =Assumptions!E$8 -> Q3'26E | F7: =Assumptions!F$8 -> Q4'26E | G7: =Assumptions!G$8 -> FY26E | H7: =Assumptions!H$8 -> Q1'27E | I7: =Assumptions!I$8 -> Q2'27E | ... R7: =Assumptions!R$8 -> NTM E
A8: Data Center | B8: ='Data Center'!B10 -> 5380 | C8: ='Data Center'!C10 -> 5775 | D8: ='Data Center'!D10 -> 6718 | E8: ='Data Center'!E10 | F8: ='Data Center'!F10 | G8: ='Data Center'!G10 | H8: ='Data Center'!H10 | I8: ='Data Center'!I10 | ... R8: ='Data Center'!R10
A9: Client | G9: =IF(COUNT(C9:F9)<4,"",SUM(C9:F9)) | L9: =IF(COUNT(H9:K9)<4,"",SUM(H9:K9)) | Q9: =IF(COUNT(M9:P9)<4,"",SUM(M9:P9)) | R9: =IF(COUNT(E9,F9,H9,I9)<4,"",SUM(E9,F9,H9,I9))
A10: Gaming | G10: =IF(COUNT(C10:F10)<4,"",SUM(C10:F10)) | L10: =IF(COUNT(H10:K10)<4,"",SUM(H10:K10)) | Q10: =IF(COUNT(M10:P10)<4,"",SUM(M10:P10)) | R10: =IF(COUNT(E10,F10,H10,I10)<4,"",SUM(E10,F10,H10,I10))
A11: Embedded | G11: =IF(COUNT(C11:F11)<4,"",SUM(C11:F11)) | L11: =IF(COUNT(H11:K11)<4,"",SUM(H11:K11)) | Q11: =IF(COUNT(M11:P11)<4,"",SUM(M11:P11)) | R11: =IF(COUNT(E11,F11,H11,I11)<4,"",SUM(E11,F11,H11,I11))
A12: Total AMD | B12: =IF(COUNT(B8:B11)=0,"",SUM(B8:B11)) -> 5380 | C12: =IF(COUNT(C8:C11)=0,"",SUM(C8:C11)) -> 5775 | D12: =IF(COUNT(D8:D11)=0,"",SUM(D8:D11)) -> 6718 | E12: =IF(COUNT(E8:E11)=0,"",SUM(E8:E11)) | F12: =IF(COUNT(F8:F11)=0,"",SUM(F8:F11)) | G12: =IF(COUNT(G8:G11)=0,"",SUM(G8:G11)) | H12: =IF(COUNT(H8:H11)=0,"",SUM(H8:H11)) | I12: =IF(COUNT(I8:I11)=0,"",SUM(I8:I11)) | ... R12: =IF(COUNT(R8:R11)=0,"",SUM(R8:R11))
A14: Data Center is the only live build. Client, Gaming and Embedded stay blank inputs on this sheet until their own driver builds exist - a blank is honest, a placeholder is not.

Sheet Assumptions
A1: AMD Revenue Model - Central Assumptions
A2: Every assumption, historical anchor, and source reference in this model lives on this sheet. The Data Center sheet holds the calculations, the interpolation, method notes, and checks.
A3: Build date 2026-08-18 | Blue on yellow = input you may edit | Black = formula | Green = link to another sheet | Red = external reference | Grey = not applicable in this column
A4: SCENARIO CONTROL
A5: Active scenario | B5: Base | C5: Type Bear, Base or Bull. Drives every "Active" cell below, and through them the whole model.
A7: 1. PERIOD AXIS - 13 quarters + 3 fiscal years + NTM. Roll the quarter here and every sheet follows.
A8: Period label | B8: Q4'25A | C8: Q1'26A | D8: Q2'26A | E8: Q3'26E | F8: Q4'26E | G8: FY26E | H8: Q1'27E | I8: Q2'27E | J8: Q3'27E | K8: Q4'27E | L8: FY27E | M8: Q1'28E | N8: Q2'28E | O8: Q3'28E | P8: Q4'28E | Q8: FY28E | R8: NTM E
A9: Period type | B9: Actual | C9: Actual | D9: Actual | E9: Estimate | F9: Estimate | G9: Fiscal year | H9: Estimate | I9: Estimate | J9: Estimate | K9: Estimate | L9: Fiscal year | M9: Estimate | N9: Estimate | O9: Estimate | P9: Estimate | Q9: Fiscal year | R9: Next 12M
A10: Quarter end / definition | B10: 2025-12-27 | C10: 2026-03-28 | D10: 2026-06-27 | E10: 2026-09-26 | F10: 2026-12-26 | G10: FY26 (Q1'26-Q4'26) | H10: 2027-03-27 | I10: 2027-06-26 | J10: 2027-09-25 | K10: 2027-12-25 | L10: FY27 (Q1'27-Q4'27) | M10: 2028-04-01 | N10: 2028-07-01 | O10: 2028-09-30 | P10: 2028-12-30 | Q10: FY28 (Q1'28-Q4'28) | R10: NTM (Q3'26E-Q2'27E)
A11: Forecast quarter index t (Q3'26E = 0) | B11: - | C11: - | D11: - | E11: 0 | F11: 1 | G11: - | H11: 2 | I11: 3 | J11: 4 | K11: 5 | L11: =AVERAGE(H11:K11) -> 3.5 | M11: 6 | N11: 7 | O11: 8 | P11: 9 | Q11: =AVERAGE(M11:P11) -> 7.5 | R11: -
A12: The index drives every interpolation. Annual columns show the average index of their four quarters; the FY28E cell (Q11) is the fade divisor, so nothing is hard-coded and the fade retargets itself when the window rolls. Rolling: relabel Q3'26E to Q3'26A, add the reported quarter to the anchor block, and shift the axis one column. Three of the 13 quarters are actual this cycle; that count runs 1-3.
A14: 2. HISTORICAL ANCHORS - reported actuals (hard) and the Server / AI split (assumption)
A15: Careful: this block is offset one quarter EARLIER than the main axis above - it runs Q3'25A to Q2'26A. The Server method needs the t-4 anchor for Q3'26E, and Q3'25 sits outside the 13-quarter window. Read this block off its own header row below, not off the period axis.
A16: Item | B16: Q3'25A | C16: Q4'25A | D16: Q1'26A | E16: Q2'26A | F16: LTM to Q2'26 | S16: Units | T16: Classification | U16: Ref
A17: Data Center segment revenue ($M) | B17: 4341 | C17: 5380 | D17: 5775 | E17: 6718 | F17: =SUM(B17:E17) -> 22214 | S17: $M | T17: Reported - hard fact | U17: R1
A18: Prior-year comparable Data Center revenue ($M) | B18: 3549 | C18: 3859 | D18: 3674 | E18: 3240 | F18: =SUM(B18:E18) -> 14322 | S18: $M | T18: Reported - hard fact (t-4) | U18: R1
A19: Server revenue ($M) [DC CPU + networking / DPU / ZT design] | B19: 2691 | C19: 3230 | D19: 3650 | E19: 3993 | F19: =SUM(B19:E19) -> 13564 | S19: $M | T19: Modeling assumption - editable | U19: R2
A20: AI revenue ($M) [Instinct / DC GPU, incl. MI450 from ramp] | B20: =B17-B19 -> 1650 | C20: =C17-C19 -> 2150 | D20: =D17-D19 -> 2125 | E20: =E17-E19 -> 2725 | F20: =SUM(B20:E20) -> 8650 | S20: $M | T20: Residual = reported total less Server | U20: R2
A21: AI share of Data Center revenue | B21: =IFERROR(B20/B17,"") -> 0.38009675 | C21: =IFERROR(C20/C17,"") -> 0.39962825 | D21: =IFERROR(D20/D17,"") -> 0.36796537 | E21: =IFERROR(E20/E17,"") -> 0.40562667 | F21: =IFERROR(F20/F17,"") -> 0.38939408 | S21: % | T21: Memo - implied by the split above
A22: AMD x86 server CPU revenue share | B22: 0.395 | C22: 0.413 | D22: 0.462 | E22: 0.49 | F22: - | S22: % share | T22: External reference - Mercury Research | U22: R3
A23: AI revenue growth, QoQ (actual) | B23: - | C23: =IFERROR(C20/B20-1,"") -> 0.3030303 | D23: =IFERROR(D20/C20-1,"") -> -0.011627907 | E23: =IFERROR(E20/D20-1,"") -> 0.28235294 | F23: - | S23: % QoQ | T23: Memo - realised path; calibrate the AI anchors (rows 35-36) to it
A24: FY25 Data Center segment revenue ($M) | B24: 16635 | C24: - | D24: - | E24: - | F24: - | S24: $M | T24: Reported - hard fact, base for the FY26E YoY memo | U24: R1
A26: 3. SERVER (DC CPU) DRIVERS - scenario anchors only. Every quarter in between is derived on the Data Center sheet.
A27: Assumption | B27: Bear | C27: Base | D27: Bull | E27: Active | F27: Units | G27: Ref | H27: Note
A28: Current x86 market growth (Q3'26E YoY) | B28: 0.35 | C28: 0.38 | D28: 0.4 | E28: =IF($B$5="Bear",B28,IF($B$5="Base",C28,D28)) -> 0.38 | F28: % YoY | G28: R4 | H28: Near-term anchor. The derived quarterly path starts here, at forecast index t = 0.
A29: Long-term x86 market growth (FY28E YoY) | B29: 0.15 | C29: 0.2 | D29: 0.25 | E29: =IF($B$5="Bear",B29,IF($B$5="Base",C29,D29)) -> 0.2 | F29: % YoY | G29: R4, R5 | H29: Long-term anchor. The fade is scaled so the four FY28E quarterly rates average to this.
A30: Current AMD x86 revenue share (Q3'26E) | B30: 0.49 | C30: 0.5 | D30: 0.51 | E30: =IF($B$5="Bear",B30,IF($B$5="Base",C30,D30)) -> 0.5 | F30: % share | G30: R3 | H30: Starting share for the forecast path, at t = 0. Historical shares are in the anchor block above.
A31: AMD share gain rate per quarter | B31: 0 | C31: 0.005 | D31: 0.01 | E31: =IF($B$5="Bear",B31,IF($B$5="Base",C31,D31)) -> 0.005 | F31: ppt/qtr | G31: R3 | H31: Added to the starting share once per forecast quarter: share(t) = current + gain x t.
A33: 4. AI (INSTINCT / DC GPU) DRIVERS - scenario anchors only. Same interpolation rule as Server.
A34: Assumption | B34: Bear | C34: Base | D34: Bull | E34: Active | F34: Units | G34: Ref | H34: Note
A35: Current AI growth (Q3'26E QoQ) | E35: =IF($B$5="Bear",IF(B35="","",B35),IF($B$5="Base",IF(C35="","",C35),IF(D35="","",D35))) | F35: % QoQ | G35: R6 | H35: Near-term anchor at t = 0. Realised QoQ history is on the anchor block above for calibration.
A36: Long-term AI growth (FY28E avg QoQ) | E36: =IF($B$5="Bear",IF(B36="","",B36),IF($B$5="Base",IF(C36="","",C36),IF(D36="","",D36))) | F36: % QoQ | G36: R6 | H36: Long-term anchor, on the same fade rule as x86 market growth.
A37: REQUIRED INPUT - the six AI cells above are intentionally blank. No AI growth path has been supplied and the build will not invent one. Until they are filled the AI line, the Data Center total, and every downstream total stay blank by design. Row 23 holds the realised QoQ history to calibrate against; MI450 belongs inside this single AI line from its ramp quarter, not in a separate row.
A39: 5. SOURCES AND REFERENCE LINKS
A40: Ref | B40: Item | F40: Classification | H40: As of | I40: Source / note | O40: Link
A41: R1 | B41: AMD reported Data Center segment revenue, Q3'25-Q2'26 and FY25 | F41: Reported (hard) | H41: 2026-08-05 | I41: AMD Selected Corporate Data (Q4'25, Q1'26, Q2'26 releases) and Q2'26 10-Q Note 4. Local copies: Financial_Tables/AMD-2025-Q4.xlsx, AMD-2026-Q1.xlsx, AMD-2026-Q2.xlsx; AMD_Obsidian/AMD_10-Q_Q2-FY2026/44-note-04-segment-reporting.md | O41: https://ir.amd.com/financial-information/quarterly-results
A42: R2 | B42: Historical Server / AI split of reported Data Center revenue | F42: Derived assumption | H42: 2026-08-13 | I42: LP reconciliation of every disclosed AMD constraint (smoothest feasible split); see revenue_modelling/BUILD_LOG.md. Supersedes the earlier hand-entered $3,300M single-quarter Q2'26 Server estimate, which could not anchor a four-quarter YoY roll.
A43: R3 | B43: AMD x86 server CPU revenue share (historical and forecast anchor) | F43: External reference | H43: 2026-05-01 | I43: Mercury Research quarterly x86 share, reported via Tom's Hardware. | O43: https://www.tomshardware.com/pc-components/cpus/amd-reaches-46-percent-of-server-x86-cpu-revenue-intel-still-controls-70-percent-of-the-consumer-pc-market-share
A44: R4 | B44: x86 server CPU market revenue growth (near-term anchor) | F44: External reference | H44: 2026-05-06 | I44: AMD Q1 2026 earnings call transcript, management commentary on server demand. | O44: https://d1io3yog0oux5.cloudfront.net/_3a6def5a328d14d7990e894d5269c4ad/amd/db/841/9232/webcast_transcript/AMD_1Q_2026_Earnings.pdf
A45: R5 | B45: AMD / Arm server CPU share gain vs Intel | F45: External reference | H45: 2026-05-20 | I45: UBS server-share summary. | O45: https://seekingalpha.com/news/4592334-amd-arm-gain-server-cpu-share-at-intels-expense-in-q1-ubs
...

Sheet Data Center
A1: AMD Data Center Revenue Build
A2: Data Center = Server + AI. Two components only.
A3: Calculations, the driver interpolation, method notes, and checks. Every assumption and source reference lives on the Assumptions sheet.
A4: Active scenario | B4: =Assumptions!$B$5 -> Base | C4: Set on Assumptions!B5.
A6: DATA CENTER REVENUE - 13 quarters, 3 fiscal years, NTM
A7: Period | B7: =Assumptions!B$8 -> Q4'25A | C7: =Assumptions!C$8 -> Q1'26A | D7: =Assumptions!D$8 -> Q2'26A | E7: =Assumptions!E$8 -> Q3'26E | F7: =Assumptions!F$8 -> Q4'26E | G7: =Assumptions!G$8 -> FY26E | H7: =Assumptions!H$8 -> Q1'27E | I7: =Assumptions!I$8 -> Q2'27E | ... R7: =Assumptions!R$8 -> NTM E
A8: Server ($M) | B8: =B24 -> 3230 | C8: =C24 -> 3650 | D8: =D24 -> 3993 | E8: =E24 -> 4700.7342 | F8: =F24 -> 5355.5433 | G8: =G24 -> 17699.278 | H8: =H24 -> 5366.9221 | I8: =I24 -> 5489.3156 | ... R8: =R24 -> 20912.515
A9: AI ($M) | B9: =B30 -> 2150 | C9: =C30 -> 2125 | D9: =D30 -> 2725 | E9: =E30 | F9: =F30 | G9: =G30 | H9: =H30 | I9: =I30 | ... R9: =R30
A10: Total Data Center revenue ($M) | B10: =IF(OR(B8="",B9=""),"",B8+B9) -> 5380 | C10: =IF(OR(C8="",C9=""),"",C8+C9) -> 5775 | D10: =IF(OR(D8="",D9=""),"",D8+D9) -> 6718 | E10: =IF(OR(E8="",E9=""),"",E8+E9) | F10: =IF(OR(F8="",F9=""),"",F8+F9) | G10: =IF(OR(G8="",G9=""),"",G8+G9) | H10: =IF(OR(H8="",H9=""),"",H8+H9) | I10: =IF(OR(I8="",I9=""),"",I8+I9) | ... R10: =IF(OR(R8="",R9=""),"",R8+R9)
A12: Memo: Data Center revenue growth, YoY | B12: =IFERROR(B10/Assumptions!$C$18-1,"") -> 0.39414356 | C12: =IFERROR(C10/Assumptions!$D$18-1,"") -> 0.57185629 | D12: =IFERROR(D10/Assumptions!$E$18-1,"") -> 1.0734568 | E12: =IFERROR(E10/Assumptions!$B$17-1,"") | F12: =IFERROR(F10/B10-1,"") | G12: =IFERROR(G10/Assumptions!$B$24-1,"") | H12: =IFERROR(H10/C10-1,"") | I12: =IFERROR(I10/D10-1,"") | J12: =IFERROR(J10/E10-1,"") | K12: =IFERROR(K10/F10-1,"") | L12: =IFERROR(L10/G10-1,"") | M12: =IFERROR(M10/H10-1,"") | N12: =IFERROR(N10/I10-1,"") | O12: =IFERROR(O10/J10-1,"") | ... Q12: =IFERROR(Q10/L10-1,"") | R12: =IFERROR(R10/Assumptions!$F$17-1,"")
A13: Memo: Data Center revenue growth, QoQ | B13: =IFERROR(B10/Assumptions!$B$17-1,"") -> 0.23934577 | C13: =IFERROR(C10/B10-1,"") -> 0.073420074 | D13: =IFERROR(D10/C10-1,"") -> 0.16329004 | E13: =IFERROR(E10/D10-1,"") | F13: =IFERROR(F10/E10-1,"") | G13: - | H13: =IFERROR(H10/F10-1,"") | I13: =IFERROR(I10/H10-1,"") | J13: =IFERROR(J10/I10-1,"") | K13: =IFERROR(K10/J10-1,"") | L13: - | M13: =IFERROR(M10/K10-1,"") | N13: =IFERROR(N10/M10-1,"") | O13: =IFERROR(O10/N10-1,"") | P13: =IFERROR(P10/O10-1,"") | Q13: - | R13: -
A14: Memo: AI share of Data Center revenue | B14: =IFERROR(B9/B10,"") -> 0.39962825 | C14: =IFERROR(C9/C10,"") -> 0.36796537 | D14: =IFERROR(D9/D10,"") -> 0.40562667 | E14: =IFERROR(E9/E10,"") | F14: =IFERROR(F9/F10,"") | G14: =IFERROR(G9/G10,"") | H14: =IFERROR(H9/H10,"") | I14: =IFERROR(I9/I10,"") | ... R14: =IFERROR(R9/R10,"")
A16: SERVER REVENUE ESTIMATION - same period axis. Anchors from Assumptions, path interpolated here.
A17: Period | B17: =Assumptions!B$8 -> Q4'25A | C17: =Assumptions!C$8 -> Q1'26A | D17: =Assumptions!D$8 -> Q2'26A | E17: =Assumptions!E$8 -> Q3'26E | F17: =Assumptions!F$8 -> Q4'26E | G17: =Assumptions!G$8 -> FY26E | H17: =Assumptions!H$8 -> Q1'27E | I17: =Assumptions!I$8 -> Q2'27E | ... R17: =Assumptions!R$8 -> NTM E
A18: Forecast quarter index t (from the period axis) | B18: - | C18: - | D18: - | E18: =Assumptions!E$11 -> 0 | F18: =Assumptions!F$11 -> 1 | G18: - | H18: =Assumptions!H$11 -> 2 | I18: =Assumptions!I$11 -> 3 | J18: =Assumptions!J$11 -> 4 | K18: =Assumptions!K$11 -> 5 | L18: - | M18: =Assumptions!M$11 -> 6 | N18: =Assumptions!N$11 -> 7 | O18: =Assumptions!O$11 -> 8 | P18: =Assumptions!P$11 -> 9 | Q18: - | R18: -
A19: x86 server CPU market revenue growth (YoY) [interpolated] | B19: - | C19: - | D19: - | E19: =IF(E18="","",Assumptions!$E$28+(Assumptions!$E$29-Assumptions!$E$28)*E18/Assumptions!$Q$11) -> 0.38 | F19: =IF(F18="","",Assumptions!$E$28+(Assumptions!$E$29-Assumptions!$E$28)*F18/Assumptions!$Q$11) -> 0.356 | G19: - | H19: =IF(H18="","",Assumptions!$E$28+(Assumptions!$E$29-Assumptions!$E$28)*H18/Assumptions!$Q$11) -> 0.332 | I19: =IF(I18="","",Assumptions!$E$28+(Assumptions!$E$29-Assumptions!$E$28)*I18/Assumptions!$Q$11) -> 0.308 | J19: =IF(J18="","",Assumptions!$E$28+(Assumptions!$E$29-Assumptions!$E$28)*J18/Assumptions!$Q$11) -> 0.284 | K19: =IF(K18="","",Assumptions!$E$28+(Assumptions!$E$29-Assumptions!$E$28)*K18/Assumptions!$Q$11) -> 0.26 | L19: - | M19: =IF(M18="","",Assumptions!$E$28+(Assumptions!$E$29-Assumptions!$E$28)*M18/Assumptions!$Q$11) -> 0.236 | N19: =IF(N18="","",Assumptions!$E$28+(Assumptions!$E$29-Assumptions!$E$28)*N18/Assumptions!$Q$11) -> 0.212 | O19: =IF(O18="","",Assumptions!$E$28+(Assumptions!$E$29-Assumptions!$E$28)*O18/Assumptions!$Q$11) -> 0.188 | P19: =IF(P18="","",Assumptions!$E$28+(Assumptions!$E$29-Assumptions!$E$28)*P18/Assumptions!$Q$11) -> 0.164 | Q19: - | R19: -
A20: AMD x86 server CPU revenue share [interpolated] | B20: =Assumptions!$C$22 -> 0.413 | C20: =Assumptions!$D$22 -> 0.462 | D20: =Assumptions!$E$22 -> 0.49 | E20: =IF(E18="","",Assumptions!$E$30+Assumptions!$E$31*E18) -> 0.5 | F20: =IF(F18="","",Assumptions!$E$30+Assumptions!$E$31*F18) -> 0.505 | G20: - | H20: =IF(H18="","",Assumptions!$E$30+Assumptions!$E$31*H18) -> 0.51 | I20: =IF(I18="","",Assumptions!$E$30+Assumptions!$E$31*I18) -> 0.515 | J20: =IF(J18="","",Assumptions!$E$30+Assumptions!$E$31*J18) -> 0.52 | K20: =IF(K18="","",Assumptions!$E$30+Assumptions!$E$31*K18) -> 0.525 | L20: - | M20: =IF(M18="","",Assumptions!$E$30+Assumptions!$E$31*M18) -> 0.53 | N20: =IF(N18="","",Assumptions!$E$30+Assumptions!$E$31*N18) -> 0.535 | O20: =IF(O18="","",Assumptions!$E$30+Assumptions!$E$31*O18) -> 0.54 | P20: =IF(P18="","",Assumptions!$E$30+Assumptions!$E$31*P18) -> 0.545 | Q20: - | R20: -
A21: Prior-year comparable AMD share (t-4) | B21: - | C21: - | D21: - | E21: =Assumptions!$B$22 -> 0.395 | F21: =B20 -> 0.413 | G21: - | H21: =C20 -> 0.462 | I21: =D20 -> 0.49 | J21: =E20 -> 0.5 | K21: =F20 -> 0.505 | L21: - | M21: =H20 -> 0.51 | N21: =I20 -> 0.515 | O21: =J20 -> 0.52 | P21: =K20 -> 0.525 | Q21: - | R21: -
A22: Prior-year comparable Server revenue (t-4) ($M) | B22: - | C22: - | D22: - | E22: =Assumptions!$B$19 -> 2691 | F22: =B24 -> 3230 | G22: - | H22: =C24 -> 3650 | I22: =D24 -> 3993 | J22: =E24 -> 4700.7342 | K22: =F24 -> 5355.5433 | L22: - | M22: =H24 -> 5366.9221 | N22: =I24 -> 5489.3156 | O22: =J24 -> 6277.1724 | P22: =K24 -> 7015.2315 | Q22: - | R22: -
A23: Implied AMD Server revenue YoY factor | B23: - | C23: - | D23: - | E23: =IF(OR(E19="",E20="",E21=""),"",(1+E19)*E20/E21) -> 1.7468354 | F23: =IF(OR(F19="",F20="",F21=""),"",(1+F19)*F20/F21) -> 1.658063 | G23: - | H23: =IF(OR(H19="",H20="",H21=""),"",(1+H19)*H20/H21) -> 1.4703896 | I23: =IF(OR(I19="",I20="",I21=""),"",(1+I19)*I20/I21) -> 1.3747347 | J23: =IF(OR(J19="",J20="",J21=""),"",(1+J19)*J20/J21) -> 1.33536 | K23: =IF(OR(K19="",K20="",K21=""),"",(1+K19)*K20/K21) -> 1.309901 | L23: - | M23: =IF(OR(M19="",M20="",M21=""),"",(1+M19)*M20/M21) -> 1.2844706 | N23: =IF(OR(N19="",N20="",N21=""),"",(1+N19)*N20/N21) -> 1.259068 | O23: =IF(OR(O19="",O20="",O21=""),"",(1+O19)*O20/O21) -> 1.2336923 | P23: =IF(OR(P19="",P20="",P21=""),"",(1+P19)*P20/P21) -> 1.2083429 | Q23: - | R23: -
A24: Server revenue ($M) | B24: =Assumptions!$C$19 -> 3230 | C24: =Assumptions!$D$19 -> 3650 | D24: =Assumptions!$E$19 -> 3993 | E24: =IF(OR(E22="",E23=""),"",E22*E23) -> 4700.7342 | F24: =IF(OR(F22="",F23=""),"",F22*F23) -> 5355.5433 | G24: =IF(COUNT(C24:F24)<4,"",SUM(C24:F24)) -> 17699.278 | H24: =IF(OR(H22="",H23=""),"",H22*H23) -> 5366.9221 | I24: =IF(OR(I22="",I23=""),"",I22*I23) -> 5489.3156 | J24: =IF(OR(J22="",J23=""),"",J22*J23) -> 6277.1724 | K24: =IF(OR(K22="",K23=""),"",K22*K23) -> 7015.2315 | L24: =IF(COUNT(H24:K24)<4,"",SUM(H24:K24)) -> 24148.642 | M24: =IF(OR(M22="",M23=""),"",M22*M23) -> 6893.6536 | N24: =IF(OR(N22="",N23=""),"",N22*N23) -> 6911.4214 | O24: =IF(OR(O22="",O23=""),"",O22*O23) -> 7744.0993 | P24: =IF(OR(P22="",P23=""),"",P22*P23) -> 8476.8049 | Q24: =IF(COUNT(M24:P24)<4,"",SUM(M24:P24)) -> 30025.979 | R24: =IF(COUNT(E24,F24,H24,I24)<4,"",SUM(E24,F24,H24,I24)) -> 20912.515
A26: AI REVENUE ESTIMATION - same period axis and the same interpolation rule.
A27: Period | B27: =Assumptions!B$8 -> Q4'25A | C27: =Assumptions!C$8 -> Q1'26A | D27: =Assumptions!D$8 -> Q2'26A | E27: =Assumptions!E$8 -> Q3'26E | F27: =Assumptions!F$8 -> Q4'26E | G27: =Assumptions!G$8 -> FY26E | H27: =Assumptions!H$8 -> Q1'27E | I27: =Assumptions!I$8 -> Q2'27E | ... R27: =Assumptions!R$8 -> NTM E
A28: AI revenue growth (QoQ) [interpolated] | B28: - | C28: - | D28: - | E28: =IF(OR(E18="",Assumptions!$E$35="",Assumptions!$E$36=""),"",Assumptions!$E$35+(Assumptions!$E$36-Assumptions!$E$35)*E18/Assumptions!$Q$11) | F28: =IF(OR(F18="",Assumptions!$E$35="",Assumptions!$E$36=""),"",Assumptions!$E$35+(Assumptions!$E$36-Assumptions!$E$35)*F18/Assumptions!$Q$11) | G28: - | H28: =IF(OR(H18="",Assumptions!$E$35="",Assumptions!$E$36=""),"",Assumptions!$E$35+(Assumptions!$E$36-Assumptions!$E$35)*H18/Assumptions!$Q$11) | I28: =IF(OR(I18="",Assumptions!$E$35="",Assumptions!$E$36=""),"",Assumptions!$E$35+(Assumptions!$E$36-Assumptions!$E$35)*I18/Assumptions!$Q$11) | J28: =IF(OR(J18="",Assumptions!$E$35="",Assumptions!$E$36=""),"",Assumptions!$E$35+(Assumptions!$E$36-Assumptions!$E$35)*J18/Assumptions!$Q$11) | K28: =IF(OR(K18="",Assumptions!$E$35="",Assumptions!$E$36=""),"",Assumptions!$E$35+(Assumptions!$E$36-Assumptions!$E$35)*K18/Assumptions!$Q$11) | L28: - | M28: =IF(OR(M18="",Assumptions!$E$35="",Assumptions!$E$36=""),"",Assumptions!$E$35+(Assumptions!$E$36-Assumptions!$E$35)*M18/Assumptions!$Q$11) | N28: =IF(OR(N18="",Assumptions!$E$35="",Assumptions!$E$36=""),"",Assumptions!$E$35+(Assumptions!$E$36-Assumptions!$E$35)*N18/Assumptions!$Q$11) | O28: =IF(OR(O18="",Assumptions!$E$35="",Assumptions!$E$36=""),"",Assumptions!$E$35+(Assumptions!$E$36-Assumptions!$E$35)*O18/Assumptions!$Q$11) | P28: =IF(OR(P18="",Assumptions!$E$35="",Assumptions!$E$36=""),"",Assumptions!$E$35+(Assumptions!$E$36-Assumptions!$E$35)*P18/Assumptions!$Q$11) | Q28: - | R28: -
A29: Prior-quarter AI revenue ($M) | B29: - | C29: - | D29: - | E29: =D30 -> 2725 | F29: =E30 | G29: - | H29: =F30 | I29: =H30 | J29: =I30 | K29: =J30 | L29: - | M29: =K30 | N29: =M30 | O29: =N30 | P29: =O30 | Q29: - | R29: -
A30: AI revenue ($M) | B30: =Assumptions!$C$20 -> 2150 | C30: =Assumptions!$D$20 -> 2125 | D30: =Assumptions!$E$20 -> 2725 | E30: =IF(OR(E29="",E28=""),"",E29*(1+E28)) | F30: =IF(OR(F29="",F28=""),"",F29*(1+F28)) | G30: =IF(COUNT(C30:F30)<4,"",SUM(C30:F30)) | H30: =IF(OR(H29="",H28=""),"",H29*(1+H28)) | I30: =IF(OR(I29="",I28=""),"",I29*(1+I28)) | J30: =IF(OR(J29="",J28=""),"",J29*(1+J28)) | K30: =IF(OR(K29="",K28=""),"",K29*(1+K28)) | L30: =IF(COUNT(H30:K30)<4,"",SUM(H30:K30)) | M30: =IF(OR(M29="",M28=""),"",M29*(1+M28)) | N30: =IF(OR(N29="",N28=""),"",N29*(1+N28)) | O30: =IF(OR(O29="",O28=""),"",O29*(1+O28)) | P30: =IF(OR(P29="",P28=""),"",P29*(1+P28)) | Q30: =IF(COUNT(M30:P30)<4,"",SUM(M30:P30)) | R30: =IF(COUNT(E30,F30,H30,I30)<4,"",SUM(E30,F30,H30,I30))
A32: METHOD - how each line is derived (all assumptions and sources: Assumptions sheet)
A33: Split | B33: Data Center = Server + AI, two components only. Server is EPYC / DC CPU plus the non-accelerator Data Center items (networking, DPU, ZT design services). AI is Instinct / DC GPU and absorbs MI450 from its ramp quarter - there is no separate new-product line.
A34: History | B34: Q4'25A, Q1'26A and Q2'26A carry AMD's reported Data Center segment revenue. AMD does not disclose the Server / AI split, so Server is a modeling assumption on Assumptions row 19 and AI is the residual. The reported total is never overridden.
A35: Interpolation | B35: ONLY THE ANCHORS ARE TYPED. Six scenario cells on Assumptions drive everything; no intermediate quarter is hard-coded. Each forecast quarter carries an index t on row 18 (Q3'26E = 0 ... Q4'28E = 9), linked from the period axis. Rates fade linearly from the current anchor toward the long-term anchor: growth(t) = current + (long_term - current) x t / t_FY28avg. Dividing by the FY28E average index rather than the last index is what makes the four FY28E quarterly rates average to the long-term anchor - which is what 'FY28E YoY' means. That divisor is itself computed from the axis, so a quarter roll retargets the fade automatically.
A36: Server | B36: Server(t) = Server(t-4) x (1 + x86 market growth YoY) x AMD share(t) / AMD share(t-4). AMD's server revenue grows with the x86 server CPU market and with its own share of it; the share ratio converts a market growth rate into an AMD growth rate. Share is a straight line, not a fade: share(t) = current share + share gain per quarter x t. Rolling off t-4 rather than t-1 keeps quarterly seasonality and stops a single anchor quarter compounding into every later period. Q3'26E reaches back to the Q3'25 anchor, just outside the 13-quarter window.
A37: AI | B37: AI(t) = AI(t-1) x (1 + QoQ growth(t)). A sequential chain, because Instinct revenue is driven by product ramp and supply timing rather than by a stable seasonal pattern. Its QoQ growth path is interpolated between the two AI anchors on Assumptions rows 35-36, on the same fade rule as above.
A38: Annual and NTM | B38: FY columns are the plain sum of their four quarters - FY26E = Q1'26A + Q2'26A + Q3'26E + Q4'26E, so FY26E is half reported. NTM E = Q3'26E + Q4'26E + Q1'27E + Q2'27E. Rate rows are marked '-' in annual and NTM columns because a growth rate does not aggregate; the annual growth memo on row 12 is computed from the revenue lines instead.
A39: Scenarios | B39: One live case at a time. Assumptions!B5 selects Bear / Base / Bull; the Active column on Assumptions resolves the six anchors, and this sheet reads only those Active cells.
A41: CHECKS
A42: Historical Server + AI ties to reported Data Center revenue | B42: =IF(SUMPRODUCT(ABS(B10:D10-Assumptions!C17:E17))<0.5,"OK","CHECK") -> OK
A43: Server split stays inside the reported total in every actual quarter | B43: =IF(SUMPRODUCT(--(Assumptions!C19:E19<0))+SUMPRODUCT(--(Assumptions!C19:E19>Assumptions!C17:E17))=0,"OK","CHECK") -> OK
A44: FY26E equals Q1'26A + Q2'26A + Q3'26E + Q4'26E | B44: =IF(G10="","PENDING AI INPUT",IF(ABS(G10-SUM(C10:F10))<0.5,"OK","CHECK")) -> PENDING AI INPUT
A45: FY27E and FY28E equal their four quarters | B45: =IF(L10="","PENDING AI INPUT",IF(AND(ABS(L10-SUM(H10:K10))<0.5,ABS(Q10-SUM(M10:P10))<0.5),"OK","CHECK")) -> PENDING AI INPUT
A46: NTM E equals Q3'26E + Q4'26E + Q1'27E + Q2'27E | B46: =IF(R10="","PENDING AI INPUT",IF(ABS(R10-(E10+F10+H10+I10))<0.5,"OK","CHECK")) -> PENDING AI INPUT
...
